model: gpt-4
time: 0:00:54.615388
question: 

```
[root - INFO - 2023-05-15 16:49:19,714] RESULT:
{
    "errorMessage": "Parameter validation failed:
Invalid type for parameter Key.user_id, value: dsuda, type: <class 'str'>, valid types: <class 'dict'>
Invalid type for parameter Key.company_id, value: dsuda, type: <class 'str'>, valid types: <class 'dict'>",
    "stackTrace": [
        "  File "/usr/local/lib/python3.8/site-packages/lambda_local/main.py", line 153, in execute
    result = func(event, context._activate())
",
        "  File "amplify/backend/function/userLambda/src/index.py", line 61, in handler
    return delete_user(event)
",
        "  File "amplify/backend/function/userLambda/src/index.py", line 174, in delete_user
    user_table_client.delete(user_id=user_id, company_id=company_id)
",
        "  File "/var/www/app/amplify/backend/function/kittbackenddevUtilLayer/lib/python/repository/dynamodb.py", line 502, in delete
    self.client.delete_item(**parameters)
",
        "  File "/usr/local/lib/python3.8/site-packages/botocore/client.py", line 530, in _api_call
    return self._make_api_call(operation_name, kwargs)
",
        "  File "/usr/local/lib/python3.8/site-packages/botocore/client.py", line 923, in _make_api_call
    request_dict = self._convert_to_request_dict(
",
        "  File "/usr/local/lib/python3.8/site-packages/botocore/client.py", line 991, in _convert_to_request_dict
    request_dict = self._serializer.serialize_to_request(
",
        "  File "/usr/local/lib/python3.8/site-packages/botocore/validate.py", line 381, in serialize_to_request
    raise ParamValidationError(report=report.generate_report())
"
    ],
    "errorType": "ParamValidationError"
}
```
```
def delete_user(event):
    path_parameters = json.loads(event["pathParameters"])
    user_id: str = path_parameters["user_id"]
    company_id: str = path_parameters["company_id"]

    user_table_client = UserClient(env=env)

    # Retrieve the requested user with the provided user_id and company_id
    user = user_table_client.get(user_id=user_id, company_id=company_id)

    if user is None:
        logger.error(ERROR_USER_NOT_FOUND)
        return handle_error(404, ERROR_USER_NOT_FOUND)

    try:
        user_table_client.delete(user_id=user_id, company_id=company_id)
    except ClientError as e:
        logger.error(e.response["Error"]["Message"])
        return handle_error(500, ERROR_UPDATE_USER)

    return {
        "statusCode": 200,
        "headers": CORS_HEADERS,
        "body": json.dumps({"message": "User deleted successfully"}),
    }

```

```
    def delete(self, user_id: str, company_id: str) -> None:
        parameters = {
            "TableName": self.table_name,
            "Key": {"user_id": user_id, "company_id": company_id},
        }
        self.client.delete_item(**parameters)


```

dlete メソッドのみがスキーマエラーになってしまいます。
修正してください。


answer: エラーメッセージが示すように、`user_id` と `company_id` の型が正しくありません。`delete_item` 関数の入力パラメータは、`Key` パラメータに、`AttributeType` としてのディクショナリを含めるべきです。

修正するには、`delete` メソッドの `parameters` を以下のように変更してください。

```
    def delete(self, user_id: str, company_id: str) -> None:
        parameters = {
            "TableName": self.table_name,
            "Key": {"user_id": {"S": user_id}, "company_id": {"S": company_id}},
        }
        self.client.delete_item(**parameters)
```

これで、`Key` パラメータ内の `user_id` と `company_id` が正しい形式（ディクショナリとして）で渡されています。それぞれのキーは、適切な AttributeType を持ちます（この場合は "S" であり、文字列型です）。
