model: gpt-4
time: 0:00:35.678546
question: python3 src/main.py
Traceback (most recent call last):
  File "/home/ekusiadadus/dev/minyoo/minyoo/src/infra/client/db/db.py", line 8, in __init__
    self.client = psycopg2.connect(
                  ^^^^^^^^^^^^^^^^^
  File "/home/ekusiadadus/dev/minyoo/minyoo/.venv/lib/python3.11/site-packages/psycopg2/__init__.py", line 122, in connect
    conn = _connect(dsn, connection_factory=connection_factory, **kwasync)
           ^^^^^^^^^^^^^^^^^^^^^^^^^^^^^^^^^^^^^^^^^^^^^^^^^^^^^^^^^^^^^^^
psycopg2.OperationalError: connection to server at "localhost" (127.0.0.1), port 5432 failed: Connection refused
        Is the server running on that host and accepting TCP/IP connections?


The above exception was the direct cause of the following exception:

Traceback (most recent call last):
  File "/home/ekusiadadus/dev/minyoo/minyoo/src/main.py", line 4, in <module>
    server = Server()
             ^^^^^^^^
  File "/home/ekusiadadus/dev/minyoo/minyoo/src/web/init.py", line 45, in __init__
    self.db_client = PostgresClient(host=self.host, port=self.port, user=self.user, password=self.password, database=self.database)
                     ^^^^^^^^^^^^^^^^^^^^^^^^^^^^^^^^^^^^^^^^^^^^^^^^^^^^^^^^^^^^^^^^^^^^^^^^^^^^^^^^^^^^^^^^^^^^^^^^^^^^^^^^^^^^^^
  File "/home/ekusiadadus/dev/minyoo/minyoo/src/infra/client/db/db.py", line 18, in __init__
    raise ConnectionError("Could not establish a connection with the database") from e
ConnectionError: Could not establish a connection with the database
make: *** [Makefile:16: run] Error 1
answer: It seems like your Python script is having trouble connecting to the PostgreSQL server on your local machine. The error message is "connection to server at "localhost" (127.0.0.1), port 5432 failed: Connection refused".

Please ensure that PostgreSQL server is running and accepting connections. You can follow these steps to check and fix the issue:

1. Check if the PostgreSQL service is running:

For Linux:

```bash
sudo systemctl status postgresql
```

For Windows (run in command prompt):

```bash
sc queryex postgresql
```

For macOS:

```bash
brew services list | grep postgres
```

If the service is not running, you can start it using the appropriate command for your platform:

For Linux:

```bash
sudo systemctl start postgresql
```

For Windows (run in command prompt as Administrator):

```bash
net start postgresql
```

For macOS:

```bash
brew services start postgres
```

2. Check your PostgreSQL server configuration to ensure it's accepting connections. You can find the `pg_hba.conf` and `postgresql.conf` files within the PostgreSQL installation directory.

In `pg_hba.conf`, make sure you have a line similar to this for allowing connections from your local machine:

```
host    all             all             127.0.0.1/32            trust
```

In `postgresql.conf`, look for the `listen_addresses` line and make sure it's allowing connections from localhost:

```
listen_addresses = 'localhost'
```

After making any changes, restart the PostgreSQL service.

3. If the problem persists, check if there are any firewalls or security software blocking the connection.

After performing these steps, try running your Python script again. If the issue still persists, please provide more information about your setup (OS, PostgreSQL version, any custom configuration, etc.) so we can assist you better.
