model: gpt-4
time: 0:01:53.066096
question: ```python:src/web/init.py
@app.websocket("/ws/chat/{user_id}/{bot_id}", name="chat")
async def websocket_endpoint(websocket: WebSocket, user_id: str, bot_id: str, server: Server = Depends(get_server)):
    await manager.connect(websocket, bot_id)
    try:
        while True:
            data = await websocket.receive_text()
            async for data in server.chat_handler.web_socket_chat(data):
                print(data)
                await manager.send_message(f"ボットID: {bot_id} ユーザーID: {user_id} メッセージ: {data}", bot_id)
    except WebSocketDisconnect:
        await manager.disconnect(websocket, bot_id)


```

```python:src/web/handlers
class ChatHandler:
    def __init__(self, chat_service: ChatService) -> None:
        self.chat_service = chat_service

    async def web_socket_chat(self, message: str):
        while True:
            try:
                res = self.chat_service.web_socket_chat(message)
            except Exception as e:
                res = ""
                print(e)
                continue
            yield str(res)
```


```python:src/domain/usecase/chat_service.py
class ChatService:
    def __init__(self, chat_history_repository: IChatHistoryRepository, bot_repository: IBotRepository, langchain_client: LangChainClient) -> None:
        self.chat_history_repository = chat_history_repository
        self.bot_repository = bot_repository
        self.langchain_client = langchain_client

    async def web_socket_chat(self, message: str):
        while True:
            try:
                res = self.langchain_client.generate_response(message)
            except Exception as e:
                res = ""
                print(e)
                continue
            yield str(res)
```

```python:src/infra/client/langchain/langchain_client.py
    async def generate_response(self, question: str):
        while True:
            try:
                response_stream = GenerateResponseType(**self.client(question))
            except Exception as e:
                response_stream = ""
                print(e)
            yield response_stream

```

```
<async_generator object ChatService.web_socket_chat at 0x7face49b1210>
<async_generator object ChatService.web_socket_chat at 0x7face49b1120>
<async_generator object ChatService.web_socket_chat at 0x7face49b1210>
<async_generator object ChatService.web_socket_chat at 0x7face49b1120>
INFO:     Shutting down
<async_generator object ChatService.web_socket_chat at 0x7face49b1210>
ERROR:    Exception in ASGI application
Traceback (most recent call last):
  File "/home/ekusiadadus/dev/minyoo/minyoo/.venv/lib/python3.11/site-packages/websockets/legacy/protocol.py", line 1302, in close_connection
    await self.transfer_data_task
  File "/home/ekusiadadus/dev/minyoo/minyoo/.venv/lib/python3.11/site-packages/websockets/legacy/protocol.py", line 959, in transfer_data
    message = await self.read_message()
              ^^^^^^^^^^^^^^^^^^^^^^^^^
  File "/home/ekusiadadus/dev/minyoo/minyoo/.venv/lib/python3.11/site-packages/websockets/legacy/protocol.py", line 1029, in read_message
    frame = await self.read_data_frame(max_size=self.max_size)
            ^^^^^^^^^^^^^^^^^^^^^^^^^^^^^^^^^^^^^^^^^^^^^^^^^^
  File "/home/ekusiadadus/dev/minyoo/minyoo/.venv/lib/python3.11/site-packages/websockets/legacy/protocol.py", line 1104, in read_data_frame
    frame = await self.read_frame(max_size)
            ^^^^^^^^^^^^^^^^^^^^^^^^^^^^^^^
  File "/home/ekusiadadus/dev/minyoo/minyoo/.venv/lib/python3.11/site-packages/websockets/legacy/protocol.py", line 1161, in read_frame
    frame = await Frame.read(
            ^^^^^^^^^^^^^^^^^
  File "/home/ekusiadadus/dev/minyoo/minyoo/.venv/lib/python3.11/site-packages/websockets/legacy/framing.py", line 68, in read
    data = await reader(2)
           ^^^^^^^^^^^^^^^
  File "/home/ekusiadadus/.rye/py/cpython@3.11.3/install/lib/python3.11/asyncio/streams.py", line 729, in readexactly
    await self._wait_for_data('readexactly')
  File "/home/ekusiadadus/.rye/py/cpython@3.11.3/install/lib/python3.11/asyncio/streams.py", line 522, in _wait_for_data
    await self._waiter
asyncio.exceptions.CancelledError

The above exception was the direct cause of the following exception:

Traceback (most recent call last):
  File "/home/ekusiadadus/dev/minyoo/minyoo/.venv/lib/python3.11/site-packages/uvicorn/protocols/websockets/websockets_impl.py", line 254, in run_asgi
    result = await self.app(self.scope, self.asgi_receive, self.asgi_send)
             ^^^^^^^^^^^^^^^^^^^^^^^^^^^^^^^^^^^^^^^^^^^^^^^^^^^^^^^^^^^^^
  File "/home/ekusiadadus/dev/minyoo/minyoo/.venv/lib/python3.11/site-packages/uvicorn/middleware/proxy_headers.py", line 78, in __call__
    return await self.app(scope, receive, send)
           ^^^^^^^^^^^^^^^^^^^^^^^^^^^^^^^^^^^^
  File "/home/ekusiadadus/dev/minyoo/minyoo/.venv/lib/python3.11/site-packages/fastapi/applications.py", line 276, in __call__
    await super().__call__(scope, receive, send)
  File "/home/ekusiadadus/dev/minyoo/minyoo/.venv/lib/python3.11/site-packages/starlette/applications.py", line 122, in __call__
    await self.middleware_stack(scope, receive, send)
  File "/home/ekusiadadus/dev/minyoo/minyoo/.venv/lib/python3.11/site-packages/starlette/middleware/errors.py", line 149, in __call__
    await self.app(scope, receive, send)
  File "/home/ekusiadadus/dev/minyoo/minyoo/.venv/lib/python3.11/site-packages/starlette/middleware/cors.py", line 75, in __call__
    await self.app(scope, receive, send)
  File "/home/ekusiadadus/dev/minyoo/minyoo/.venv/lib/python3.11/site-packages/starlette/middleware/exceptions.py", line 79, in __call__
    raise exc
  File "/home/ekusiadadus/dev/minyoo/minyoo/.venv/lib/python3.11/site-packages/starlette/middleware/exceptions.py", line 68, in __call__
    await self.app(scope, receive, sender)
  File "/home/ekusiadadus/dev/minyoo/minyoo/.venv/lib/python3.11/site-packages/fastapi/middleware/asyncexitstack.py", line 21, in __call__
    raise e
  File "/home/ekusiadadus/dev/minyoo/minyoo/.venv/lib/python3.11/site-packages/fastapi/middleware/asyncexitstack.py", line 18, in __call__
    await self.app(scope, receive, send)
  File "/home/ekusiadadus/dev/minyoo/minyoo/.venv/lib/python3.11/site-packages/starlette/routing.py", line 718, in __call__
    await route.handle(scope, receive, send)
  File "/home/ekusiadadus/dev/minyoo/minyoo/.venv/lib/python3.11/site-packages/starlette/routing.py", line 341, in handle
    await self.app(scope, receive, send)
  File "/home/ekusiadadus/dev/minyoo/minyoo/.venv/lib/python3.11/site-packages/starlette/routing.py", line 82, in app
    await func(session)
  File "/home/ekusiadadus/dev/minyoo/minyoo/.venv/lib/python3.11/site-packages/fastapi/routing.py", line 289, in app
    await dependant.call(**values)
  File "/home/ekusiadadus/dev/minyoo/minyoo/src/web/init.py", line 162, in websocket_endpoint
    await manager.send_message(f"ボットID: {bot_id} ユーザーID: {user_id} メッセージ: {data}", bot_id)
  File "/home/ekusiadadus/dev/minyoo/minyoo/src/web/init.py", line 41, in send_message
    await connection.send_text(message)
  File "/home/ekusiadadus/dev/minyoo/minyoo/.venv/lib/python3.11/site-packages/starlette/websockets.py", line 163, in send_text
    await self.send({"type": "websocket.send", "text": data})
  File "/home/ekusiadadus/dev/minyoo/minyoo/.venv/lib/python3.11/site-packages/starlette/websockets.py", line 85, in send
    await self._send(message)
  File "/home/ekusiadadus/dev/minyoo/minyoo/.venv/lib/python3.11/site-packages/starlette/middleware/exceptions.py", line 65, in sender
    await send(message)
  File "/home/ekusiadadus/dev/minyoo/minyoo/.venv/lib/python3.11/site-packages/uvicorn/protocols/websockets/websockets_impl.py", line 327, in asgi_send
    await self.send(data)  # type: ignore[arg-type]
    ^^^^^^^^^^^^^^^^^^^^^
  File "/home/ekusiadadus/dev/minyoo/minyoo/.venv/lib/python3.11/site-packages/websockets/legacy/protocol.py", line 635, in send
    await self.ensure_open()
  File "/home/ekusiadadus/dev/minyoo/minyoo/.venv/lib/python3.11/site-packages/websockets/legacy/protocol.py", line 944, in ensure_open
    raise self.connection_closed_exc()
websockets.exceptions.ConnectionClosedError: sent 1012 (service restart); no close frame received
INFO:     connection closed
^CINFO:     Finished server process [1084]
ERROR:    Traceback (most recent call last):
  File "/home/ekusiadadus/dev/minyoo/minyoo/.venv/lib/python3.11/site-packages/starlette/routing.py", line 686, in lifespan
    await receive()
  File "/home/ekusiadadus/dev/minyoo/minyoo/.venv/lib/python3.11/site-packages/uvicorn/lifespan/on.py", line 139, in receive
    return await self.receive_queue.get()
           ^^^^^^^^^^^^^^^^^^^^^^^^^^^^^^
  File "/home/ekusiadadus/.rye/py/cpython@3.11.3/install/lib/python3.11/asyncio/queues.py", line 158, in get
    await getter
asyncio.exceptions.CancelledError
```

上のようにエラーになってしまいます。
どのように修正すればいいですか？
ステップバイステップでコードの修正方法を教えてください。
answer: このエラーメッセージから、ウェブソケットの接続が切れた後に例外が発生しているように見えます。まず、`websocket.send_text`が呼び出される前に、ウェブソケットの接続がまだ開いているかどうかを確認することをお勧めします。

また、`web_socket_chat`関数とそれに関連する他の関数を `async def` から `def` に変更し、ジェネレータを使用する代わりにフルコルーチンを使用することを検討してください。

以下に示すようにコードを変更してください: 

1. asyncジェネレータをコルーチンに変更し、ChatHandlerクラスの関数を修正します。

```python:src/web/handlers.py
class ChatHandler:
    def __init__(self, chat_service: ChatService) -> None:
        self.chat_service = chat_service

    async def web_socket_chat(self, message: str):        
        try:
            res = await self.chat_service.web_socket_chat(message)
        except Exception as e:
            res = ""
            print(e)

        return str(res)
```

2. ChatServiceクラスの関数を以下のように修正して、asyncジェネレータを使わないようにします。

```python:src/domain/usecase/chat_service.py
class ChatService:
    def __init__(self, chat_history_repository: IChatHistoryRepository, bot_repository: IBotRepository, langchain_client: LangChainClient) -> None:
        self.chat_history_repository = chat_history_repository
        self.bot_repository = bot_repository
        self.langchain_client = langchain_client

    async def web_socket_chat(self, message: str):        
        try:
            res = await self.langchain_client.generate_response(message)
        except Exception as e:
            res = ""
            print(e)

        return str(res)
```

3. LangChainClientの関数もasyncジェネレータを使わないように修正します。

```python:src/infra/client/langchain/langchain_client.py
    async def generate_response(self, question: str):        
        try:
            response_stream = GenerateResponseType(**self.client(question))
        except Exception as e:
            response_stream = ""
            print(e)

        return response_stream
```

4. 最後に、`websocket_endpoint`関数を修正して、新しい`web_socket_chat`関数との互換性を持たせます。

```python:src/web/init.py
@app.websocket("/ws/chat/{user_id}/{bot_id}", name="chat")
async def websocket_endpoint(websocket: WebSocket, user_id: str, bot_id: str, server: Server = Depends(get_server)):
    await manager.connect(websocket, bot_id)
    try:
        while True:
            data = await websocket.receive_text()
            res = await server.chat_handler.web_socket_chat(data)
            print(res)
            await manager.send_message(f"ボットID: {bot_id} ユーザーID: {user_id} メッセージ: {res}", bot_id)
    except WebSocketDisconnect:
        await manager.disconnect(websocket, bot_id)
```

これらの変更により、コードが正しく動作することを確認してください。ウェブソケットの接続が切れた場合でも、`ConnectionClosedError`とその関連の例外が発生しないようになります。
