model: gpt-4
time: 0:01:21.890859
question: 

```python
import time
import json
import os
import logging

from botocore.exceptions import ClientError

try:
    from repository import UserClient
    from models import User
except Exception:
    import sys

    sys.path.append("amplify/backend/function/kittbackenddevUtilLayer/lib/python")
    from repository import UserClient
    from models import User

logging.basicConfig(level=logging.INFO)
logger = logging.getLogger(__name__)
logger.setLevel(logging.INFO)
env = os.environ["ENV"]

ERROR_USER_NOT_FOUND = "user not found"
ERROR_UPDATE_USER = "Error in updating user to DynamoDB"

CORS_HEADERS = {
    "Access-Control-Allow-Headers": "*",
    "Access-Control-Allow-Origin": "*",
    "Access-Control-Allow-Methods": "OPTIONS,POST,GET",
}

def handle_error(status_code, error_message):
    return {
        "statusCode": status_code,
        "headers": CORS_HEADERS,
        "body": json.dumps({"error": error_message}),
    }


def handler(event, context):
    input_data = json.loads(event["body"])

    user_id = input_data["user_id"]
    company_id = input_data["company_id"]
    family_name = input_data["family_name"]
    given_name = input_data["given_name"]
    email = input_data["email"]

    user_table_client = UserClient(env=env)

    user = user_table_client.get(user_id=user_id, company_id=company_id)

    if user is None:
        logger.error(ERROR_USER_NOT_FOUND)
        return handle_error(404, ERROR_USER_NOT_FOUND)

    user = User(
        user_id=user_id,
        company_id=company_id,
        family_name=family_name,
        given_name=given_name,
        email=email,
        created_at=user.created_at,
        updated_at=int(time.time()),
    )

    try:
        user_table_client.update(user=user)
    except ClientError as e:
        logger.error(e.response["Error"]["Message"])
        return handle_error(500, ERROR_UPDATE_USER)
```

```
class User(BaseModel):
    user_id: str
    company_id: str
    user_type: Optional[Literal["DEVELOPER", "ADMINISTRATOR", "ENDUSER"]]
    email: Optional[str]
    icon_url: Optional[str]
    family_name: Optional[str]
    given_name: Optional[str]
    is_active: Optional[bool]
    created_at: Optional[int]
    updated_at: Optional[int]

    @classmethod
    def from_dynamo_item(cls, item: dict) -> "User":
        deserialized = {k: deserializer.deserialize(v) for k, v in item.items()}
        return cls(**deserialized)
```

```
    def get(self, user_id: str, company_id: str) -> User:

        partitionKey = user_id
        sortKey = company_id

        parameters = {
            "TableName": self.table_name,
            "IndexName": self.company_id_index,
            "Select": "ALL_ATTRIBUTES",
            "KeyConditionExpression": "user_id = :user_id AND company_id = :company_id",
            "ExpressionAttributeValues": {
                ":user_id": {"S": user_id},
                ":company_id": {"S": company_id},
            },
        }

        res = self.client.query(**parameters)
        if "Items" not in res:
            raise KeyError(
                f'''Item with the couple of keys not found.
            Partition Key: {partitionKey}, Sort Key: {sortKey}'''
            )
        return User.from_dynamo_item(res["Items"][0])
```

```
{
    "errorMessage": "list index out of range",
    "stackTrace": [
        "  File "/usr/local/lib/python3.8/site-packages/lambda_local/main.py", line 153, in execute
    result = func(event, context._activate())
",
        "  File "amplify/backend/function/updateUser/src/index.py", line 73, in handler
    user = user_table_client.get(user_id=user_id, company_id=company_id)
",
        "  File "/var/www/app/amplify/backend/function/kittbackenddevUtilLayer/lib/python/repository/dynamodb.py", line 426, in get
    return User.from_dynamo_item(res["Items"][0])
"
    ],
    "errorType": "IndexError"
}
```

```
    return {
        "statusCode": 200,
        "headers": CORS_HEADERS,
        "body": json.dumps({"user": user.to_dict()}),
    }

```

上のコードで、update に成功した場合、`user.to_dict()` を返すようにしようと思っています。
メソッドの追加方法がわからないので、教えていただけると助かります。
また、これより良い方法があれば教えてください。


answer: クラス`User`にメソッド`to_dict`を追加するには、次のように定義します。

```python
class User(BaseModel):
    # 既存の属性とメソッドはここに

    def to_dict(self) -> dict:
        return self.dict()
```

これにより、`User`インスタンスの`to_dict()`メソッドを呼び出すことで、そのインスタンスのデータを辞書形式で取得できます。

つまり、次のようになります。

```python
return {
    "statusCode": 200,
    "headers": CORS_HEADERS,
    "body": json.dumps({"user": user.to_dict()}),
}
```

ただし、この方法は`BaseModel`が`dict()`メソッドを持っていることを仮定しています。一部のバージョンの pydantic.models ではこれがサポートされていない場合があるため、その場合は次のようにして対応できます。

```python
class User(BaseModel):
    # 既存の属性とメソッドはここに

    def to_dict(self) -> dict:
        return {
            "user_id": self.user_id,
            "company_id": self.company_id,
            "user_type": self.user_type,
            "email": self.email,
            "icon_url": self.icon_url,
            "family_name": self.family_name,
            "given_name": self.given_name,
            "is_active": self.is_active,
            "created_at": self.created_at,
            "updated_at": self.updated_at,
        }
```

これで、`user.to_dict()` が期待通りに動作するはずです。
