model: gpt-4
time: 0:00:58.732535
question: 

```python
import time
import json
import os
import logging

from botocore.exceptions import ClientError

try:
    from repository import UserClient
    from models import User
except Exception:
    import sys

    sys.path.append("amplify/backend/function/kittbackenddevUtilLayer/lib/python")
    from repository import UserClient
    from models import User

logging.basicConfig(level=logging.INFO)
logger = logging.getLogger(__name__)
logger.setLevel(logging.INFO)
env = os.environ["ENV"]

ERROR_USER_NOT_FOUND = "user not found"
ERROR_UPDATE_USER = "Error in updating user to DynamoDB"

CORS_HEADERS = {
    "Access-Control-Allow-Headers": "*",
    "Access-Control-Allow-Origin": "*",
    "Access-Control-Allow-Methods": "OPTIONS,POST,GET",
}

def handle_error(status_code, error_message):
    return {
        "statusCode": status_code,
        "headers": CORS_HEADERS,
        "body": json.dumps({"error": error_message}),
    }


def handler(event, context):
    input_data = json.loads(event["body"])

    user_id = input_data["user_id"]
    company_id = input_data["company_id"]
    family_name = input_data["family_name"]
    given_name = input_data["given_name"]
    email = input_data["email"]

    user_table_client = UserClient(env=env)

    user = user_table_client.get(user_id=user_id, company_id=company_id)

    if user is None:
        logger.error(ERROR_USER_NOT_FOUND)
        return handle_error(404, ERROR_USER_NOT_FOUND)

    user = User(
        user_id=user_id,
        company_id=company_id,
        family_name=family_name,
        given_name=given_name,
        email=email,
        created_at=user.created_at,
        updated_at=int(time.time()),
    )

    try:
        user_table_client.update(user=user)
    except ClientError as e:
        logger.error(e.response["Error"]["Message"])
        return handle_error(500, ERROR_UPDATE_USER)
```

```
class User(BaseModel):
    user_id: str
    company_id: str
    user_type: Optional[Literal["DEVELOPER", "ADMINISTRATOR", "ENDUSER"]]
    email: Optional[str]
    icon_url: Optional[str]
    family_name: Optional[str]
    given_name: Optional[str]
    is_active: Optional[bool]
    created_at: Optional[int]
    updated_at: Optional[int]

    @classmethod
    def from_dynamo_item(cls, item: dict) -> "User":
        deserialized = {k: deserializer.deserialize(v) for k, v in item.items()}
        return cls(**deserialized)
```

```
    def get(self, user_id: str, company_id: str) -> User:

        partitionKey = user_id
        sortKey = company_id

        parameters = {
            "TableName": self.table_name,
            "IndexName": self.company_id_index,
            "Select": "ALL_ATTRIBUTES",
            "KeyConditionExpression": "user_id = :user_id AND company_id = :company_id",
            "ExpressionAttributeValues": {
                ":user_id": {"S": user_id},
                ":company_id": {"S": company_id},
            },
        }

        res = self.client.query(**parameters)
        if "Items" not in res:
            raise KeyError(
                f'''Item with the couple of keys not found.
            Partition Key: {partitionKey}, Sort Key: {sortKey}'''
            )
        return User.from_dynamo_item(res["Items"][0])
```

```
{
    "errorMessage": "list index out of range",
    "stackTrace": [
        "  File "/usr/local/lib/python3.8/site-packages/lambda_local/main.py", line 153, in execute
    result = func(event, context._activate())
",
        "  File "amplify/backend/function/updateUser/src/index.py", line 73, in handler
    user = user_table_client.get(user_id=user_id, company_id=company_id)
",
        "  File "/var/www/app/amplify/backend/function/kittbackenddevUtilLayer/lib/python/repository/dynamodb.py", line 426, in get
    return User.from_dynamo_item(res["Items"][0])
"
    ],
    "errorType": "IndexError"
}
```

上のコードで、dynamoDBに存在しない場合の処理をより良いものにしたいです。
dynamoDBに存在しないときのエラー処理を追加してください。


answer: エラー処理を追加するために、`get`メソッドの最後の部分を以下のように変更してください。

```python
# Before:
if "Items" not in res:
    raise KeyError(
        f'''Item with the couple of keys not found.
    Partition Key: {partitionKey}, Sort Key: {sortKey}'''
    )
return User.from_dynamo_item(res["Items"][0])

# After:
if "Items" in res and len(res["Items"]) > 0:
    return User.from_dynamo_item(res["Items"][0])
else:
    return None
```

これにより、`get`メソッドは`Items`が空の場合に`None`を返すようになります。これにより、`handler`関数内で、`user`が`None`の場合のエラー処理が適切に行われます。すでに`handler`関数には以下のエラー処理が含まれています。

```python
if user is None:
    logger.error(ERROR_USER_NOT_FOUND)
    return handle_error(404, ERROR_USER_NOT_FOUND)
```
